Workbook
Name ListaDevs: #REF!

Sheet Instruções
A1: Como preencher a aba “Ranking_Expert”: 1. Em projeto_id, escolha um dos projetos (P1…P5). O nome do projeto aparece automaticamente ao lado. 2. Em rank_expert, escolha o ranking da equipe: 2.1. 1 = melhor equipe que você montaria hoje para esse projeto, 2.2. 2 = segunda melhor alternativa, … até 5. 3. Em nota_global, atribua uma nota de 1 a 5 para a equipe, considerando quão boa ela é para o projeto. 4. Em observações, escreva livremente os critérios usados e comentário que julgar importante. 5. Para cada projeto (P1…P5), preencha até 5 equipes (rank 1 a 5), onde 1 é a melhor e 5 a pior.
A18: OSF | B18: Fator de sucesso objetivo | E18: Ex.: NPS
A19: SLF | B19: Fator de liderança subjetiva (a nível de equipe) | E19: Ex.: Time avalia sua liderança na equipe

Sheet Devs
A1: id | B1: nome_apelido | C1: dominio | D1: ecossistema | E1: linguagens | F1: resumo_projetos_em_comum_na_equipe
A2: 5 | B2: Dev5 | C2: Mobile | D2: Android | E2: Kotlin | F2: 5-263: P179(,osf=0.489,slf=0.711) | 5-468: P82(,osf=0.567,slf=0.737) | 5-503: P145(,osf=0.612,slf=0.871); P177(,osf=0.340,slf=0.621); P213(,osf=0.312,slf=0.608); P216(,osf=0.401,slf=0.341); P279(,osf=0.594,slf=0.422)
A3: 7 | B3: Dev7 | C3: Web | D3: React | E3: JavaScript | F3: 7-193: P82(,osf=0.567,slf=0.737); P85(,osf=0.784,slf=0.538) | 7-194: P40(,osf=0.733,slf=0.373); P82(,osf=0.567,slf=0.737); P85(,osf=0.784,slf=0.538)
A4: 8 | B4: Dev8 | C4: IoT | F4: 8-142: P104(,osf=0.636,slf=0.624); P175(,osf=0.716,slf=0.339); P205(,osf=0.588,slf=0.465); P92(,osf=0.849,slf=0.891) | 8-290: P175(,osf=0.716,slf=0.339); P205(,osf=0.588,slf=0.465); P92(,osf=0.849,slf=0.891)
A5: 27 | B5: Dev27 | C5: Web | E5: JavaScript | F5: 27-363: P103(,osf=0.739,slf=0.847); P123(,osf=0.393,slf=0.825); P144(,osf=0.541,slf=0.688); P145(,osf=0.612,slf=0.871); P148(,osf=0.411,slf=0.639); P149(,osf=0.325,slf=0.603); P150(,osf=0.475,slf=0.317); P171(,osf=0.486,slf=0.531); P177(,osf=0.340,slf=0.621); P179(,osf=0.489,slf=0.711); P239(,osf=0.422,slf=0.462); P240(,osf=0.385,slf=0.409); P258(,osf=0.666,slf=0.352); P72(,osf=0.639,slf=0.456); P80(,osf=0.559,slf=0.624); P82(,osf=0.567,slf=0.737); P85(,osf=0.784,slf=0.538); P99(,osf=0.757,slf=0.452)
A6: 29 | B6: Dev29 | C6: Web | D6: Vue | E6: JavaScript | F6: 29-524: P106(,osf=0.303,slf=0.349); P262(,osf=0.819,slf=0.404)
A7: 33 | B7: Dev33 | D7: Android, CouchDB, iOS/iPadOS | E7: JavaScript | F7: SEM_HISTORICO_COMUM_COM_MEMBROS_DA_EQUIPE_NA_AMOSTRA
A8: 36 | B8: Dev36 | C8: Mobile | D8: Android | E8: Kotlin | F8: 36-181: P82(,osf=0.567,slf=0.737)
A9: 38 | B9: Dev38 | C9: Web | D9: iOS/iPadOS | F9: 38-225: P82(,osf=0.567,slf=0.737)
A10: 62 | B10: Dev62 | D10: MongoDB, iOS/iPadOS | F10: 62-415: P85(,osf=0.784,slf=0.538)
A11: 71 | B11: Dev71 | C11: IoT, Web | D11: iOS/iPadOS | E11: HTML, JavaScript, Python | F11: SEM_HISTORICO_COMUM_COM_MEMBROS_DA_EQUIPE_NA_AMOSTRA
A12: 81 | B12: Dev81 | C12: IoT | E12: JavaScript | F12: 81-104: P69(,osf=0.478,slf=0.301)
A13: 93 | B13: Dev93 | C13: Desktop | D13: .NET | E13: C# | F13: 93-270: P82(,osf=0.567,slf=0.737) | 93-292: P82(,osf=0.567,slf=0.737) | 93-437: P158(,osf=0.670,slf=0.322); P82(,osf=0.567,slf=0.737); P85(,osf=0.784,slf=0.538)
A14: 103 | B14: Dev103 | C14: Web | D14: Angular | E14: TypeScript | F14: 103-544: P82(,osf=0.567,slf=0.737); P85(,osf=0.784,slf=0.538)
A15: 104 | B15: Dev104 | C15: Mobile | D15: Android | E15: Kotlin | F15: 104-81: P69(,osf=0.478,slf=0.301)
A16: 115 | B16: Dev115 | C16: Web | D16: Node.js | E16: JavaScript | F16: SEM_HISTORICO_COMUM_COM_MEMBROS_DA_EQUIPE_NA_AMOSTRA
A17: 119 | B17: Dev119 | C17: Mobile | D17: iOS/iPadOS | E17: Swift | F17: 119-193: P82(,osf=0.567,slf=0.737) | 119-399: P82(,osf=0.567,slf=0.737)
A18: 142 | B18: Dev142 | C18: Mobile | D18: Android | E18: Kotlin | F18: 142-8: P104(,osf=0.636,slf=0.624); P175(,osf=0.716,slf=0.339); P205(,osf=0.588,slf=0.465); P92(,osf=0.849,slf=0.891) | 142-290: P175(,osf=0.716,slf=0.339); P205(,osf=0.588,slf=0.465); P242(,osf=0.558,slf=0.665); P253(,osf=0.540,slf=0.837); P71(,osf=0.523,slf=0.674); P79(,osf=0.323,slf=0.442); P82(,osf=0.567,slf=0.737); P85(,osf=0.784,slf=0.538); P92(,osf=0.849,slf=0.891)
A19: 143 | B19: Dev143 | C19: Cloud | D19: AWS Lambda | E19: Python | F19: 143-370: P68(,osf=0.644,slf=0.857)
A20: 145 | B20: Dev145 | C20: IoT, Web | D20: iOS/iPadOS | E20: JSON, JavaScript | F20: 145-263: P179(,osf=0.489,slf=0.711); P201(,osf=0.535,slf=0.596)
A21: 154 | B21: Dev154 | C21: Cloud | D21: AWS Lambda | E21: Python | F21: SEM_HISTORICO_COMUM_COM_MEMBROS_DA_EQUIPE_NA_AMOSTRA
A22: 169 | B22: Dev169 | C22: Web | D22: React | E22: JavaScript | F22: SEM_HISTORICO_COMUM_COM_MEMBROS_DA_EQUIPE_NA_AMOSTRA
A23: 174 | B23: Dev174 | C23: Web | D23: Vue | E23: JavaScript | F23: SEM_HISTORICO_COMUM_COM_MEMBROS_DA_EQUIPE_NA_AMOSTRA
A24: 181 | B24: Dev181 | C24: Cloud | D24: AWS Lambda | E24: Python | F24: 181-36: P82(,osf=0.567,slf=0.737)
... A78: 391 | B78: Dev391 | C78: Cloud | D78: AWS Lambda | E78: Python | F78: SEM_HISTORICO_COMUM_COM_MEMBROS_DA_EQUIPE_NA_AMOSTRA
A79: 152 | B79: Dev152 | C79: Web | D79: React | E79: JavaScript
A80: 465 | B80: Dev465 | C80: Web | D80: Spring Boot | E80: Java
A81: 362 | B81: Dev362 | C81: Web | D81: React | E81: JavaScript | F81: SEM_HISTORICO_COMUM_COM_MEMBROS_DA_EQUIPE_NA_AMOSTRA
A82: 242 | B82: Dev242 | C82: Web | D82: Node.js | E82: JavaScript | F82: SEM_HISTORICO_COMUM_COM_MEMBROS_DA_EQUIPE_NA_AMOSTRA
A83: 450 | B83: Dev450 | C83: Desktop | D83: .NET | E83: C# | F83: SEM_HISTORICO_COMUM_COM_MEMBROS_DA_EQUIPE_NA_AMOSTRA
A84: 161 | B84: Dev161 | C84: N/A | D84: N/A | E84: JavaScript | F84: SEM_HISTORICO_COMUM_COM_MEMBROS_DA_EQUIPE_NA_AMOSTRA | G84: Web | H84: React | I84: JavaScript | J84: 423-558: P85(,osf=0.784,slf=0.538)
A85: 354 | B85: Dev354 | C85: Web | D85: Node.js | E85: JavaScript | F85: SEM_HISTORICO_COMUM_COM_MEMBROS_DA_EQUIPE_NA_AMOSTRA
A86: 495 | B86: Dev495 | C86: Web | D86: Spring Boot | E86: Java | F86: SEM_HISTORICO_COMUM_COM_MEMBROS_DA_EQUIPE_NA_AMOSTRA
A87: 458 | B87: Dev458 | C87: Mobile | D87: iOS/iPadOS | E87: Swift | F87: SEM_HISTORICO_COMUM_COM_MEMBROS_DA_EQUIPE_NA_AMOSTRA
A88: 16 | B88: Dev16 | C88: N/A | D88: iOS/iPadOS | E88: N/A | F88: SEM_HISTORICO_COMUM_COM_MEMBROS_DA_EQUIPE_NA_AMOSTRA
A89: 463 | B89: Dev463 | C89: Web | D89: Vue | E89: JavaScript | F89: SEM_HISTORICO_COMUM_COM_MEMBROS_DA_EQUIPE_NA_AMOSTRA
A90: 65 | B90: Dev65 | C90: IoT;Web | D90: iOS/iPadOS | E90: C++;Java | F90: 65-261: P11(,osf=0.460,slf=0.781); P76(,osf=0.821,slf=0.637); P118(,osf=0.593,slf=0.504)
A91: 63 | B91: Dev63 | C91: IoT | D91: N/A | E91: Lua;Java | F91: SEM_HISTORICO_COMUM_COM_MEMBROS_DA_EQUIPE_NA_AMOSTRA
A92: 261 | B92: Dev261 | C92: Cloud | D92: AWS Lambda | E92: Python | F92: 261-65: P76(,osf=0.821,slf=0.637); P11(,osf=0.460,slf=0.781); P118(,osf=0.593,slf=0.504)
A93: 335 | B93: Dev335 | C93: Desktop | D93: .NET | E93: C# | F93: 335-508: P196(,osf=0.888,slf=0.339) | 335-193: P85(,osf=0.784,slf=0.538); P82(,osf=0.567,slf=0.737) | 335-36: P82(,osf=0.567,slf=0.737)
...

Sheet Projetos
A1: projeto_id | B1: nome | C1: descricao_curta | D1: dominio_must | E1: dominio_should | F1: dominio_could | G1: ecossistema_must | H1: ecossistema_should | I1: ecossistema_could | J1: linguagens_must | K1: linguagens_should | L1: linguagens_could
A2: P_ | B2: <nome_do_projeto>
A3: P1 | B3: .NET Corporate Portal Maintainance | C3: Internal corporate portal in .NET, with both desktop and web components, critical for administrative routines. Objective: fix bugs, improve performance, and gradually modernize the front-end without disrupting operations. | D3: Desktop, Web | E3: Cloud | F3: Mobile | G3: .NET | H3: React | I3: MongoDB | J3: C# | K3: JavaScript, TypeScript | L3: Python
A4: P2 | B4: Hybrid Mobile App with Web Panel | C4: Mobile application for Android and iOS consuming an existing backend, with a simple web panel for support. Focus on UX, good cross-platform communication, and stable backend integration. | D4: Mobile | E4: Web | F4: Cloud | G4: Android, iOS/iPadOS | H4: React | I4: .NET | J4: Kotlin, Swift | K4: JavaScript, TypeScript | L4: Java, C#
A5: P3 | B5: Cloud IoT Sensor Platform | C5: Platform to collect IoT sensor data, process it in the cloud, and display it on a web dashboard. Focus on robust data ingestion, cloud processing, and minimal but functional visualization. | D5: IoT, Cloud | E5: Web | F5: Desktop | G5: AWS Lambda | H5: React, Angular, MongoDB | I5: Android | J5: Python, C++ | K5: JavaScript | L5: Java, TypeScript
A6: P4 | B6: Web Analytic Reports SaaS | C6: Web-based SaaS application for generating dashboards and analytical reports using MongoDB data. Emphasis on efficient queries, solid data modeling, and a clear visualization interface. | D6: Web | E6: Cloud | F6: Desktop | G6: MongoDB | H6: Angular, React | I6: AWS Lambda | J6: JavaScript | K6: TypeScript, Python | L6: Java, C#
A7: P5 | B7: Critical Web + Cloud Platform | C7: Mission-critical Web + Cloud system with a React front-end, serverless backend on AWS Lambda, and MongoDB database. Requires high reliability, testing, monitoring, and scalability. | D7: Web, Cloud | E7: Mobile | F7: Desktop | G7: React, AWS Lambda, MongoDB | H7: .NET | I7: Android | J7: JavaScript, TypeScript, Python | K7: C#, Java | L7: Kotlin, Swift
A8: P6 | B8: Critical Embedded Hardware Platform | C8: Development of an electronic board (PCB) and embedded firmware for a mission-critical device. Includes board design, prototyping, bring-up, drivers, sensor reading/actuator control, bench testing, and validation. | D8: Hardware, Embedded | E8: IoT | F8: Cloud | G8: PCB, Desenvolvimento de Placa | H8: Eletrônica (circuitos lógicos e analógicos) | I8: Instrumentação (osciloscópio, analisador lógico), Prototipação | J8: C | K8: C++ (se tiver firmware mais complexo) | L8: Python (scripts de teste/automação de bancada)

Sheet Ranking_Expert
A1: projeto_id | B1: projeto e requisitos | C1: equipe_id | D1: dev1 | E1: dev2 | F1: dev3 | G1: dev4 | H1: rank_expert | I1: nota_global | J1: observações | K1: team_match_summary | L1: DOM_M | M1: DOM_S | N1: DOM_C | O1: ECO_M | P1: ECO_S | Q1: ECO_C | R1: LING_M | S1: LING_S | T1: LING_C | U1: MUST_OK | V1: FALTAS_MUST | W1: TOTAL_FALTAS_MUST | X1: note_dev1 | Y1: note_dev2 | Z1: note_dev3 | AA1: note_dev4
A2: P1 | B2: =IFERROR(VLOOKUP(A2,Projetos!$A$2:$C$7,2,FALSE),"") -> .NET Corporate Portal Maintainance | C2: P1-TEAM0 | D2: Dev169 | E2: Dev27 | F2: Dev81 | G2: Dev363 | H2: 3 | I2: 4 | K2: DOM M(1/2)[web] S(0/1)[] C(1/1)[mobile] | ECO M(0/1)[] S(1/1)[react] C(0/1)[] | LING M(0/1)[] S(1/2)[javascript] C(0/1)[] | L2: =IFERROR(__xludf.DUMMYFUNCTION("IFERROR(REGEXEXTRACT($K2,""DOM\s*M\((\d+/\d+)\)""),"""") "),"1/2") -> 1/2 | M2: =IFERROR(__xludf.DUMMYFUNCTION("IFERROR(REGEXEXTRACT($K2,""DOM.*?S\((\d+/\d+)\)""),"""") "),"0/1") -> 0/1 | N2: =IFERROR(__xludf.DUMMYFUNCTION("IFERROR(REGEXEXTRACT($K2,""DOM.*?C\((\d+/\d+)\)""),"""") "),"1/1") -> 1/1 | O2: =IFERROR(__xludf.DUMMYFUNCTION("IFERROR(REGEXEXTRACT($K2,""ECO\s*M\((\d+/\d+)\)""),"""") "),"0/1") -> 0/1 | P2: =IFERROR(__xludf.DUMMYFUNCTION("IFERROR(REGEXEXTRACT($K2,""ECO.*?S\((\d+/\d+)\)""),"""") "),"1/1") -> 1/1 | Q2: =IFERROR(__xludf.DUMMYFUNCTION("IFERROR(REGEXEXTRACT($K2,""ECO.*?C\((\d+/\d+)\)""),"""") "),"0/1") -> 0/1 | R2: =IFERROR(__xludf.DUMMYFUNCTION("IFERROR(REGEXEXTRACT($K2,""LING\s*M\((\d+/\d+)\)""),"""") "),"0/1") -> 0/1 | S2: =IFERROR(__xludf.DUMMYFUNCTION("IFERROR(REGEXEXTRACT($K2,""LING.*?S\((\d+/\d+)\)""),"""") "),"1/2") -> 1/2 | T2: =IFERROR(__xludf.DUMMYFUNCTION("IFERROR(REGEXEXTRACT($K2,""LING[^|]*C\(([0-9]+/[0-9]+)\)""),"""") "),"0/1") -> 0/1 | U2: =IFERROR(__xludf.DUMMYFUNCTION("AND( VALUE(INDEX(SPLIT(L2,""/""),1))=VALUE(INDEX(SPLIT(L2,""/""),2)), VALUE(INDEX(SPLIT(O2,""/""),1))=VALUE(INDEX(SPLIT(O2,""/""),2)), VALUE(INDEX(SPLIT(R2,""/""),1))=VALUE(INDEX(SPLIT(R2,""/""),2)) ) "),FALSE) -> FALSE | V2: =IFERROR(__xludf.DUMMYFUNCTION("IF($U2=TRUE,""OK"", TEXTJOIN("" | "",TRUE, IF(VALUE(INDEX(SPLIT($L2,""/""),2))-VALUE(INDEX(SPLIT($L2,""/""),1))>0, ""DOM faltam ""&(VALUE(INDEX(SPLIT($L2,""/""),2))-VALUE(INDEX(SPLIT($L2,""/""),1))), """"), IF(VALUE(INDEX(SPLIT($O2,""/""),2))-V"&"ALUE(INDEX(SPLIT($O2,""/""),1))>0, ""ECO faltam ""&(VALUE(INDEX(SPLIT($O2,""/""),2))-VALUE(INDEX(SPLIT($O2,""/""),1))), """"), IF(VALUE(INDEX(SPLIT($R2,""/""),2))-VALUE(INDEX(SPLIT($R2,""/""),1))>0, ""LING faltam ""&(VALUE(INDEX(SPLIT($R2,""/"&"""),2))-VALUE(INDEX(SPLIT($R2,""/""),1))), """") ) ) "),"DOM faltam 1 | ECO faltam 1 | LING faltam 1") -> DOM faltam 1 | ECO faltam 1 | LING faltam 1 | W2: =IFERROR(__xludf.DUMMYFUNCTION(" (VALUE(INDEX(SPLIT(L2,""/""),2))-VALUE(INDEX(SPLIT(L2,""/""),1))) + (VALUE(INDEX(SPLIT(O2,""/""),2))-VALUE(INDEX(SPLIT(O2,""/""),1))) + (VALUE(INDEX(SPLIT(R2,""/""),2))-VALUE(INDEX(SPLIT(R2,""/""),1))) "),3.0) -> 3 | X2: Domínio: Web Ecossistema: React Linguagens: JavaScript Match (requisitos do projeto): DOM: M (1/2)[web] S (0/1)[] C (0/1)[] ECO: M (0/1)[] S (1/1)[react] C (0/1)[] LING: M (0/1)[] S (1/2)[javascript] C (0/1)[] Colaboração (somente com membros desta equipe): 169-27: SEM_COMUM 169-81: SEM_COMUM 169-363: SEM_COMUM | Y2: Domínio: Web Ecossistema: nan Linguagens: JavaScript Match (requisitos do projeto): DOM: M (1/2)[web] S (0/1)[] C (0/1)[] ECO: M (0/1)[] S (0/1)[] C (0/1)[] LING: M (0/1)[] S (1/2)[javascript] C (0/1)[] Colaboração (somente com membros desta equipe): 27-81: SEM_COMUM 27-169: SEM_COMUM 27-363: P103(,osf=0.739,slf=0.847); P123(,osf=0.393,slf=0.825); P144(,osf=0.541,slf=0.688); P145(,osf=0.612,slf=0.871); P148(,osf=0.411,slf=0.639); P149(,osf=0.325,slf=0.603); P150(,osf=0.475,slf=0.317); P171(,osf=0.486,slf=0.531); P177(,osf=0.340,slf=0.621); P179(,osf=0.489,slf=0.711); P239(,osf=0.422,slf=0.462); P240(,osf=0.385,slf=0.409); P258(,osf=0.666,slf=0.352); P72(,osf=0.639,slf=0.456); P80(,osf=0.559,slf=0.624); P82(,osf=0.567,slf=0.737); P85(,osf=0.784,slf=0.538); P99(,osf=0.757,slf=0.452) | Z2: Domínio: IoT Ecossistema: nan Linguagens: JavaScript Match (requisitos do projeto): DOM: M (0/2)[] S (0/1)[] C (0/1)[] ECO: M (0/1)[] S (0/1)[] C (0/1)[] LING: M (0/1)[] S (1/2)[javascript] C (0/1)[] Colaboração (somente com membros desta equipe): 81-27: SEM_COMUM 81-169: SEM_COMUM 81-363: SEM_COMUM | AA2: Domínio: Mobile Ecossistema: iOS/iPadOS Linguagens: Swift Match (requisitos do projeto): DOM: M (0/2)[] S (0/1)[] C (1/1)[mobile] ECO: M (0/1)[] S (0/1)[] C (0/1)[] LING: M (0/1)[] S (0/2)[] C (0/1)[] Colaboração (somente com membros desta equipe): 363-27: P103(,osf=0.739,slf=0.847); P123(,osf=0.393,slf=0.825); P144(,osf=0.541,slf=0.688); P145(,osf=0.612,slf=0.871); P148(,osf=0.411,slf=0.639); P149(,osf=0.325,slf=0.603); P150(,osf=0.475,slf=0.317); P171(,osf=0.486,slf=0.531); P177(,osf=0.340,slf=0.621); P179(,osf=0.489,slf=0.711); P239(,osf=0.422,slf=0.462); P240(,osf=0.385,slf=0.409); P258(,osf=0.666,slf=0.352); P72(,osf=0.639,slf=0.456); P80(,osf=0.559,slf=0.624); P82(,osf=0.567,slf=0.737); P85(,osf=0.784,slf=0.538); P99(,osf=0.757,slf=0.452) | 363-447: P123(,osf=0.393,slf=0.825); P144(,osf=0.541,slf=0.688); P145(,osf=0.612,slf=0.871); P148(,osf=0.411,slf=0.639); P149(,osf=0.325,slf=0.603); P150(,osf=0.475,slf=0.317); P171(,osf=0.486,slf=0.531); P177(,osf=0.340,slf=0.621); P179(,osf=0.489,slf=0.711); P214(,osf=0.335,slf=0.820); P239(,osf=0.422,slf=0.462); P240(,osf=0.385,slf=0.409); P258(,osf=0.666,slf=0.352); P82(,osf=0.567,slf=0.737); P85(,osf=0.784,slf=0.538) | 363-544: P123(,osf=0.393,slf=0.825); P144(,osf=0.541,slf=0.688); P145(,osf=0.612,slf=0.871); P148(,osf=0.411,slf=0.639); P149(,osf=0.325,slf=0.603); P150(,osf=0.475,slf=0.317); P171(,osf=0.486,slf=0.531); P177(,osf=0.340,slf=0.621); P179(,osf=0.489,slf=0.711); P239(,osf=0.422,slf=0.462); P240(,osf=0.385,slf=0.409); P258(,osf=0.666,slf=0.352); P82(,osf=0.567,slf=0.737); P85(,osf=0.784,slf=0.538) 363-81: SEM_COMUM 363-169: SEM_COMUM
B3: =IFERROR( "DOM M["&VLOOKUP($A2,Projetos!$A:$L,4,FALSE)&"] S["&VLOOKUP($A2,Projetos!$A:$L,5,FALSE)&"] C["&VLOOKUP($A2,Projetos!$A:$L,6,FALSE)&"]"&CHAR(10)& "ECO M["&VLOOKUP($A2,Projetos!$A:$L,7,FALSE)&"] S["&VLOOKUP($A2,Projetos!$A:$L,8,FALSE)&"] C["&VLOOKUP($A2,Projetos!$A:$L,9,FALSE)&"]"&CHAR(10)& "LING M["&VLOOKUP($A2,Projetos!$A:$L,10,FALSE)&"] S["&VLOOKUP($A2,Projetos!$A:$L,11,FALSE)&"] C["&VLOOKUP($A2,Projetos!$A:$L,12,FALSE)&"]" ,"") -> DOM M[Desktop, Web] S[Cloud] C[Mobile] ECO M[.NET] S[React] C[MongoDB] LING M[C#] S[JavaScript, TypeScript] C[Python] | C3: P1-TEAM1 | D3: Dev71 | E3: Dev518 | F3: Dev509 | G3: Dev439 | H3: 4 | I3: 5 | K3: DOM M(1/2)[web] S(0/1)[] C(0/1)[] | ECO M(0/1)[] S(1/1)[react] C(0/1)[] | LING M(0/1)[] S(2/2)[javascript, typescript] C(1/1)[python] | L3: =IFERROR(__xludf.DUMMYFUNCTION("IFERROR(REGEXEXTRACT($K3,""DOM\s*M\((\d+/\d+)\)""),"""") "),"1/2") -> 1/2 | M3: =IFERROR(__xludf.DUMMYFUNCTION("IFERROR(REGEXEXTRACT($K3,""DOM.*?S\((\d+/\d+)\)""),"""") "),"0/1") -> 0/1 | N3: =IFERROR(__xludf.DUMMYFUNCTION("IFERROR(REGEXEXTRACT($K3,""DOM.*?C\((\d+/\d+)\)""),"""") "),"0/1") -> 0/1 | O3: =IFERROR(__xludf.DUMMYFUNCTION("IFERROR(REGEXEXTRACT($K3,""ECO\s*M\((\d+/\d+)\)""),"""") "),"0/1") -> 0/1 | P3: =IFERROR(__xludf.DUMMYFUNCTION("IFERROR(REGEXEXTRACT($K3,""ECO.*?S\((\d+/\d+)\)""),"""") "),"1/1") -> 1/1 | Q3: =IFERROR(__xludf.DUMMYFUNCTION("IFERROR(REGEXEXTRACT($K3,""ECO.*?C\((\d+/\d+)\)""),"""") "),"0/1") -> 0/1 | R3: =IFERROR(__xludf.DUMMYFUNCTION("IFERROR(REGEXEXTRACT($K3,""LING\s*M\((\d+/\d+)\)""),"""") "),"0/1") -> 0/1 | S3: =IFERROR(__xludf.DUMMYFUNCTION("IFERROR(REGEXEXTRACT($K3,""LING.*?S\((\d+/\d+)\)""),"""") "),"2/2") -> 2/2 | T3: =IFERROR(__xludf.DUMMYFUNCTION("IFERROR(REGEXEXTRACT($K3,""LING[^|]*C\(([0-9]+/[0-9]+)\)""),"""") "),"1/1") -> 1/1 | U3: =IFERROR(__xludf.DUMMYFUNCTION("AND( VALUE(INDEX(SPLIT(L3,""/""),1))=VALUE(INDEX(SPLIT(L3,""/""),2)), VALUE(INDEX(SPLIT(O3,""/""),1))=VALUE(INDEX(SPLIT(O3,""/""),2)), VALUE(INDEX(SPLIT(R3,""/""),1))=VALUE(INDEX(SPLIT(R3,""/""),2)) ) "),FALSE) -> FALSE | V3: =IFERROR(__xludf.DUMMYFUNCTION("IF($U3=TRUE,""OK"", TEXTJOIN("" | "",TRUE, IF(VALUE(INDEX(SPLIT($L3,""/""),2))-VALUE(INDEX(SPLIT($L3,""/""),1))>0, ""DOM faltam ""&(VALUE(INDEX(SPLIT($L3,""/""),2))-VALUE(INDEX(SPLIT($L3,""/""),1))), """"), IF(VALUE(INDEX(SPLIT($O3,""/""),2))-V"&"ALUE(INDEX(SPLIT($O3,""/""),1))>0, ""ECO faltam ""&(VALUE(INDEX(SPLIT($O3,""/""),2))-VALUE(INDEX(SPLIT($O3,""/""),1))), """"), IF(VALUE(INDEX(SPLIT($R3,""/""),2))-VALUE(INDEX(SPLIT($R3,""/""),1))>0, ""LING faltam ""&(VALUE(INDEX(SPLIT($R3,""/"&"""),2))-VALUE(INDEX(SPLIT($R3,""/""),1))), """") ) ) "),"DOM faltam 1 | ECO faltam 1 | LING faltam 1") -> DOM faltam 1 | ECO faltam 1 | LING faltam 1 | W3: =IFERROR(__xludf.DUMMYFUNCTION(" (VALUE(INDEX(SPLIT(L3,""/""),2))-VALUE(INDEX(SPLIT(L3,""/""),1))) + (VALUE(INDEX(SPLIT(O3,""/""),2))-VALUE(INDEX(SPLIT(O3,""/""),1))) + (VALUE(INDEX(SPLIT(R3,""/""),2))-VALUE(INDEX(SPLIT(R3,""/""),1))) "),3.0) -> 3
C4: P1-TEAM2 | D4: Dev205 | E4: Dev526 | F4: Dev363 | G4: Dev447 | H4: 4 | I4: 5 | K4: DOM M(1/2)[web] S(0/1)[] C(1/1)[mobile] | ECO M(0/1)[] S(1/1)[react] C(0/1)[] | LING M(0/1)[] S(1/2)[javascript] C(0/1)[] | L4: =IFERROR(__xludf.DUMMYFUNCTION("IFERROR(REGEXEXTRACT($K4,""DOM\s*M\((\d+/\d+)\)""),"""") "),"1/2") -> 1/2 | M4: =IFERROR(__xludf.DUMMYFUNCTION("IFERROR(REGEXEXTRACT($K4,""DOM.*?S\((\d+/\d+)\)""),"""") "),"0/1") -> 0/1 | N4: =IFERROR(__xludf.DUMMYFUNCTION("IFERROR(REGEXEXTRACT($K4,""DOM.*?C\((\d+/\d+)\)""),"""") "),"1/1") -> 1/1 | O4: =IFERROR(__xludf.DUMMYFUNCTION("IFERROR(REGEXEXTRACT($K4,""ECO\s*M\((\d+/\d+)\)""),"""") "),"0/1") -> 0/1 | P4: =IFERROR(__xludf.DUMMYFUNCTION("IFERROR(REGEXEXTRACT($K4,""ECO.*?S\((\d+/\d+)\)""),"""") "),"1/1") -> 1/1 | Q4: =IFERROR(__xludf.DUMMYFUNCTION("IFERROR(REGEXEXTRACT($K4,""ECO.*?C\((\d+/\d+)\)""),"""") "),"0/1") -> 0/1 | R4: =IFERROR(__xludf.DUMMYFUNCTION("IFERROR(REGEXEXTRACT($K4,""LING\s*M\((\d+/\d+)\)""),"""") "),"0/1") -> 0/1 | S4: =IFERROR(__xludf.DUMMYFUNCTION("IFERROR(REGEXEXTRACT($K4,""LING.*?S\((\d+/\d+)\)""),"""") "),"1/2") -> 1/2 | T4: =IFERROR(__xludf.DUMMYFUNCTION("IFERROR(REGEXEXTRACT($K4,""LING[^|]*C\(([0-9]+/[0-9]+)\)""),"""") "),"0/1") -> 0/1 | U4: =IFERROR(__xludf.DUMMYFUNCTION("AND( VALUE(INDEX(SPLIT(L4,""/""),1))=VALUE(INDEX(SPLIT(L4,""/""),2)), VALUE(INDEX(SPLIT(O4,""/""),1))=VALUE(INDEX(SPLIT(O4,""/""),2)), VALUE(INDEX(SPLIT(R4,""/""),1))=VALUE(INDEX(SPLIT(R4,""/""),2)) ) "),FALSE) -> FALSE | V4: =IFERROR(__xludf.DUMMYFUNCTION("IF($U4=TRUE,""OK"", TEXTJOIN("" | "",TRUE, IF(VALUE(INDEX(SPLIT($L4,""/""),2))-VALUE(INDEX(SPLIT($L4,""/""),1))>0, ""DOM faltam ""&(VALUE(INDEX(SPLIT($L4,""/""),2))-VALUE(INDEX(SPLIT($L4,""/""),1))), """"), IF(VALUE(INDEX(SPLIT($O4,""/""),2))-V"&"ALUE(INDEX(SPLIT($O4,""/""),1))>0, ""ECO faltam ""&(VALUE(INDEX(SPLIT($O4,""/""),2))-VALUE(INDEX(SPLIT($O4,""/""),1))), """"), IF(VALUE(INDEX(SPLIT($R4,""/""),2))-VALUE(INDEX(SPLIT($R4,""/""),1))>0, ""LING faltam ""&(VALUE(INDEX(SPLIT($R4,""/"&"""),2))-VALUE(INDEX(SPLIT($R4,""/""),1))), """") ) ) "),"DOM faltam 1 | ECO faltam 1 | LING faltam 1") -> DOM faltam 1 | ECO faltam 1 | LING faltam 1 | W4: =IFERROR(__xludf.DUMMYFUNCTION(" (VALUE(INDEX(SPLIT(L4,""/""),2))-VALUE(INDEX(SPLIT(L4,""/""),1))) + (VALUE(INDEX(SPLIT(O4,""/""),2))-VALUE(INDEX(SPLIT(O4,""/""),1))) + (VALUE(INDEX(SPLIT(R4,""/""),2))-VALUE(INDEX(SPLIT(R4,""/""),1))) "),3.0) -> 3 | X4: Domínio: Mobile Ecossistema: Android Linguagens: Kotlin Match (requisitos do projeto): DOM: M (0/2)[] S (0/1)[] C (1/1)[mobile] ECO: M (0/1)[] S (0/1)[] C (0/1)[] LING: M (0/1)[] S (0/2)[] C (0/1)[] Colaboração (somente com membros desta equipe): 205-363: SEM_COMUM 205-447: SEM_COMUM 205-526: P139(,osf=0.325,slf=0.436) | Y4: Domínio: Web Ecossistema: React Linguagens: JavaScript Match (requisitos do projeto): DOM: M (1/2)[web] S (0/1)[] C (0/1)[] ECO: M (0/1)[] S (1/1)[react] C (0/1)[] LING: M (0/1)[] S (1/2)[javascript] C (0/1)[] Colaboração (somente com membros desta equipe): 526-205: P139(,osf=0.325,slf=0.436) 526-363: SEM_COMUM 526-447: SEM_COMUM | Z4: Domínio: Mobile Ecossistema: iOS/iPadOS Linguagens: Swift Match (requisitos do projeto): DOM: M (0/2)[] S (0/1)[] C (1/1)[mobile] ECO: M (0/1)[] S (0/1)[] C (0/1)[] LING: M (0/1)[] S (0/2)[] C (0/1)[] Colaboração (somente com membros desta equipe): 363-205: SEM_COMUM 363-447: SEM_COMUM 363-526: SEM_COMUM | AA4: Domínio: Mobile Ecossistema: iOS/iPadOS Linguagens: Swift Match (requisitos do projeto): DOM: M (0/2)[] S (0/1)[] C (1/1)[mobile] ECO: M (0/1)[] S (0/1)[] C (0/1)[] LING: M (0/1)[] S (0/2)[] C (0/1)[] Colaboração (somente com membros desta equipe): 447-205: SEM_COMUM 447-363: P123(,osf=0.393,slf=0.825); P144(,osf=0.541,slf=0.688); P145(,osf=0.612,slf=0.871); P148(,osf=0.411,slf=0.639); P149(,osf=0.325,slf=0.603); P150(,osf=0.475,slf=0.317); P171(,osf=0.486,slf=0.531); P177(,osf=0.340,slf=0.621); P179(,osf=0.489,slf=0.711); P214(,osf=0.335,slf=0.820); P239(,osf=0.422,slf=0.462); P240(,osf=0.385,slf=0.409); P258(,osf=0.666,slf=0.352); P82(,osf=0.567,slf=0.737); P85(,osf=0.784,slf=0.538) 447-526: SEM_COMUM
C5: P1-TEAM3 | D5: Dev33 | E5: Dev303 | F5: Dev270 | G5: Dev93 | H5: 2 | I5: 3 | K5: DOM M(2/2)[desktop, web] S(0/1)[] C(0/1)[] | ECO M(1/1)[.net] S(0/1)[] C(0/1)[] | LING M(1/1)[c#] S(2/2)[javascript, typescript] C(0/1)[] | L5: =IFERROR(__xludf.DUMMYFUNCTION("IFERROR(REGEXEXTRACT($K5,""DOM\s*M\((\d+/\d+)\)""),"""") "),"2/2") -> 2/2 | M5: =IFERROR(__xludf.DUMMYFUNCTION("IFERROR(REGEXEXTRACT($K5,""DOM.*?S\((\d+/\d+)\)""),"""") "),"0/1") -> 0/1 | N5: =IFERROR(__xludf.DUMMYFUNCTION("IFERROR(REGEXEXTRACT($K5,""DOM.*?C\((\d+/\d+)\)""),"""") "),"0/1") -> 0/1 | O5: =IFERROR(__xludf.DUMMYFUNCTION("IFERROR(REGEXEXTRACT($K5,""ECO\s*M\((\d+/\d+)\)""),"""") "),"1/1") -> 1/1 | P5: =IFERROR(__xludf.DUMMYFUNCTION("IFERROR(REGEXEXTRACT($K5,""ECO.*?S\((\d+/\d+)\)""),"""") "),"0/1") -> 0/1 | Q5: =IFERROR(__xludf.DUMMYFUNCTION("IFERROR(REGEXEXTRACT($K5,""ECO.*?C\((\d+/\d+)\)""),"""") "),"0/1") -> 0/1 | R5: =IFERROR(__xludf.DUMMYFUNCTION("IFERROR(REGEXEXTRACT($K5,""LING\s*M\((\d+/\d+)\)""),"""") "),"1/1") -> 1/1 | S5: =IFERROR(__xludf.DUMMYFUNCTION("IFERROR(REGEXEXTRACT($K5,""LING.*?S\((\d+/\d+)\)""),"""") "),"2/2") -> 2/2 | T5: =IFERROR(__xludf.DUMMYFUNCTION("IFERROR(REGEXEXTRACT($K5,""LING[^|]*C\(([0-9]+/[0-9]+)\)""),"""") "),"0/1") -> 0/1 | U5: =IFERROR(__xludf.DUMMYFUNCTION("AND( VALUE(INDEX(SPLIT(L5,""/""),1))=VALUE(INDEX(SPLIT(L5,""/""),2)), VALUE(INDEX(SPLIT(O5,""/""),1))=VALUE(INDEX(SPLIT(O5,""/""),2)), VALUE(INDEX(SPLIT(R5,""/""),1))=VALUE(INDEX(SPLIT(R5,""/""),2)) ) "),TRUE) -> TRUE | V5: =IFERROR(__xludf.DUMMYFUNCTION("IF($U5=TRUE,""OK"", TEXTJOIN("" | "",TRUE, IF(VALUE(INDEX(SPLIT($L5,""/""),2))-VALUE(INDEX(SPLIT($L5,""/""),1))>0, ""DOM faltam ""&(VALUE(INDEX(SPLIT($L5,""/""),2))-VALUE(INDEX(SPLIT($L5,""/""),1))), """"), IF(VALUE(INDEX(SPLIT($O5,""/""),2))-V"&"ALUE(INDEX(SPLIT($O5,""/""),1))>0, ""ECO faltam ""&(VALUE(INDEX(SPLIT($O5,""/""),2))-VALUE(INDEX(SPLIT($O5,""/""),1))), """"), IF(VALUE(INDEX(SPLIT($R5,""/""),2))-VALUE(INDEX(SPLIT($R5,""/""),1))>0, ""LING faltam ""&(VALUE(INDEX(SPLIT($R5,""/"&"""),2))-VALUE(INDEX(SPLIT($R5,""/""),1))), """") ) ) "),"OK") -> OK | W5: =IFERROR(__xludf.DUMMYFUNCTION(" (VALUE(INDEX(SPLIT(L5,""/""),2))-VALUE(INDEX(SPLIT(L5,""/""),1))) + (VALUE(INDEX(SPLIT(O5,""/""),2))-VALUE(INDEX(SPLIT(O5,""/""),1))) + (VALUE(INDEX(SPLIT(R5,""/""),2))-VALUE(INDEX(SPLIT(R5,""/""),1))) "),0.0) -> 0 | X5: Domínio: nan Ecossistema: Android, CouchDB, iOS/iPadOS Linguagens: JavaScript Match (requisitos do projeto): DOM: M (0/2)[] S (0/1)[] C (0/1)[] ECO: M (0/1)[] S (0/1)[] C (0/1)[] LING: M (0/1)[] S (1/2)[javascript] C (0/1)[] Colaboração (somente com membros desta equipe): 33-93: SEM_COMUM 33-270: SEM_COMUM 33-303: SEM_COMUM | Y5: Domínio: Desktop Ecossistema: .NET Linguagens: C# Match (requisitos do projeto): DOM: M (1/2)[desktop] S (0/1)[] C (0/1)[] ECO: M (1/1)[.net] S (0/1)[] C (0/1)[] LING: M (1/1)[c#] S (0/2)[] C (0/1)[] Colaboração (somente com membros desta equipe): 303-33: SEM_COMUM 303-93: SEM_COMUM 303-270: SEM_COMUM | Z5: Domínio: Web Ecossistema: Angular Linguagens: TypeScript Match (requisitos do projeto): DOM: M (1/2)[web] S (0/1)[] C (0/1)[] ECO: M (0/1)[] S (0/1)[] C (0/1)[] LING: M (0/1)[] S (1/2)[typescript] C (0/1)[] Colaboração (somente com membros desta equipe): 270-33: SEM_COMUM 270-93: P82(,osf=0.567,slf=0.737) | 270-411: P82(,osf=0.567,slf=0.737) | 270-438: P82(,osf=0.567,slf=0.737) 270-303: SEM_COMUM | AA5: Domínio: Desktop Ecossistema: .NET Linguagens: C# Match (requisitos do projeto): DOM: M (1/2)[desktop] S (0/1)[] C (0/1)[] ECO: M (1/1)[.net] S (0/1)[] C (0/1)[] LING: M (1/1)[c#] S (0/2)[] C (0/1)[] Colaboração (somente com membros desta equipe): 93-33: SEM_COMUM 93-270: P82(,osf=0.567,slf=0.737) | 93-292: P82(,osf=0.567,slf=0.737) | 93-437: P158(,osf=0.670,slf=0.322); P82(,osf=0.567,slf=0.737); P85(,osf=0.784,slf=0.538) 93-303: SEM_COMUM
C6: P1-TEAM4 | D6: Dev316 | E6: Dev389 | F6: Dev526 | G6: Dev308 | H6: 2 | I6: 3 | K6: DOM M(1/2)[web] S(0/1)[] C(1/1)[mobile] | ECO M(0/1)[] S(1/1)[react] C(0/1)[] | LING M(0/1)[] S(1/2)[javascript] C(0/1)[] | L6: =IFERROR(__xludf.DUMMYFUNCTION("IFERROR(REGEXEXTRACT($K6,""DOM\s*M\((\d+/\d+)\)""),"""") "),"1/2") -> 1/2 | M6: =IFERROR(__xludf.DUMMYFUNCTION("IFERROR(REGEXEXTRACT($K6,""DOM.*?S\((\d+/\d+)\)""),"""") "),"0/1") -> 0/1 | N6: =IFERROR(__xludf.DUMMYFUNCTION("IFERROR(REGEXEXTRACT($K6,""DOM.*?C\((\d+/\d+)\)""),"""") "),"1/1") -> 1/1 | O6: =IFERROR(__xludf.DUMMYFUNCTION("IFERROR(REGEXEXTRACT($K6,""ECO\s*M\((\d+/\d+)\)""),"""") "),"0/1") -> 0/1 | P6: =IFERROR(__xludf.DUMMYFUNCTION("IFERROR(REGEXEXTRACT($K6,""ECO.*?S\((\d+/\d+)\)""),"""") "),"1/1") -> 1/1 | Q6: =IFERROR(__xludf.DUMMYFUNCTION("IFERROR(REGEXEXTRACT($K6,""ECO.*?C\((\d+/\d+)\)""),"""") "),"0/1") -> 0/1 | R6: =IFERROR(__xludf.DUMMYFUNCTION("IFERROR(REGEXEXTRACT($K6,""LING\s*M\((\d+/\d+)\)""),"""") "),"0/1") -> 0/1 | S6: =IFERROR(__xludf.DUMMYFUNCTION("IFERROR(REGEXEXTRACT($K6,""LING.*?S\((\d+/\d+)\)""),"""") "),"1/2") -> 1/2 | T6: =IFERROR(__xludf.DUMMYFUNCTION("IFERROR(REGEXEXTRACT($K6,""LING[^|]*C\(([0-9]+/[0-9]+)\)""),"""") "),"0/1") -> 0/1 | U6: =IFERROR(__xludf.DUMMYFUNCTION("AND( VALUE(INDEX(SPLIT(L6,""/""),1))=VALUE(INDEX(SPLIT(L6,""/""),2)), VALUE(INDEX(SPLIT(O6,""/""),1))=VALUE(INDEX(SPLIT(O6,""/""),2)), VALUE(INDEX(SPLIT(R6,""/""),1))=VALUE(INDEX(SPLIT(R6,""/""),2)) ) "),FALSE) -> FALSE | V6: =IFERROR(__xludf.DUMMYFUNCTION("IF($U6=TRUE,""OK"", TEXTJOIN("" | "",TRUE, IF(VALUE(INDEX(SPLIT($L6,""/""),2))-VALUE(INDEX(SPLIT($L6,""/""),1))>0, ""DOM faltam ""&(VALUE(INDEX(SPLIT($L6,""/""),2))-VALUE(INDEX(SPLIT($L6,""/""),1))), """"), IF(VALUE(INDEX(SPLIT($O6,""/""),2))-V"&"ALUE(INDEX(SPLIT($O6,""/""),1))>0, ""ECO faltam ""&(VALUE(INDEX(SPLIT($O6,""/""),2))-VALUE(INDEX(SPLIT($O6,""/""),1))), """"), IF(VALUE(INDEX(SPLIT($R6,""/""),2))-VALUE(INDEX(SPLIT($R6,""/""),1))>0, ""LING faltam ""&(VALUE(INDEX(SPLIT($R6,""/"&"""),2))-VALUE(INDEX(SPLIT($R6,""/""),1))), """") ) ) "),"DOM faltam 1 | ECO faltam 1 | LING faltam 1") -> DOM faltam 1 | ECO faltam 1 | LING faltam 1 | W6: =IFERROR(__xludf.DUMMYFUNCTION(" (VALUE(INDEX(SPLIT(L6,""/""),2))-VALUE(INDEX(SPLIT(L6,""/""),1))) + (VALUE(INDEX(SPLIT(O6,""/""),2))-VALUE(INDEX(SPLIT(O6,""/""),1))) + (VALUE(INDEX(SPLIT(R6,""/""),2))-VALUE(INDEX(SPLIT(R6,""/""),1))) "),3.0) -> 3 | X6: Domínio: Web Ecossistema: Node.js Linguagens: JavaScript Match (requisitos do projeto): DOM: M (1/2)[web] S (0/1)[] C (0/1)[] ECO: M (0/1)[] S (0/1)[] C (0/1)[] LING: M (0/1)[] S (1/2)[javascript] C (0/1)[] Colaboração (somente com membros desta equipe): 316-308: SEM_COMUM 316-389: SEM_COMUM 316-526: SEM_COMUM | Y6: Domínio: Mobile Ecossistema: Android Linguagens: Kotlin Match (requisitos do projeto): DOM: M (0/2)[] S (0/1)[] C (1/1)[mobile] ECO: M (0/1)[] S (0/1)[] C (0/1)[] LING: M (0/1)[] S (0/2)[] C (0/1)[] Colaboração (somente com membros desta equipe): 389-308: SEM_COMUM 389-316: SEM_COMUM 389-526: SEM_COMUM | Z6: Domínio: Web Ecossistema: React Linguagens: JavaScript Match (requisitos do projeto): DOM: M (1/2)[web] S (0/1)[] C (0/1)[] ECO: M (0/1)[] S (1/1)[react] C (0/1)[] LING: M (0/1)[] S (1/2)[javascript] C (0/1)[] Colaboração (somente com membros desta equipe): 526-308: SEM_COMUM 526-316: SEM_COMUM 526-389: SEM_COMUM | AA6: Domínio: Web Ecossistema: React Linguagens: JavaScript Match (requisitos do projeto): DOM: M (1/2)[web] S (0/1)[] C (0/1)[] ECO: M (0/1)[] S (1/1)[react] C (0/1)[] LING: M (0/1)[] S (1/2)[javascript] C (0/1)[] Colaboração (somente com membros desta equipe): 308-316: SEM_COMUM 308-389: SEM_COMUM 308-526: SEM_COMUM
L7: =IFERROR(__xludf.DUMMYFUNCTION("IFERROR(REGEXEXTRACT($K7,""DOM\s*M\((\d+/\d+)\)""),"""") "),"") | M7: =IFERROR(__xludf.DUMMYFUNCTION("IFERROR(REGEXEXTRACT($K7,""DOM.*?S\((\d+/\d+)\)""),"""") "),"") | N7: =IFERROR(__xludf.DUMMYFUNCTION("IFERROR(REGEXEXTRACT($K7,""DOM.*?C\((\d+/\d+)\)""),"""") "),"") | O7: =IFERROR(__xludf.DUMMYFUNCTION("IFERROR(REGEXEXTRACT($K7,""ECO\s*M\((\d+/\d+)\)""),"""") "),"") | P7: =IFERROR(__xludf.DUMMYFUNCTION("IFERROR(REGEXEXTRACT($K7,""ECO.*?S\((\d+/\d+)\)""),"""") "),"") | Q7: =IFERROR(__xludf.DUMMYFUNCTION("IFERROR(REGEXEXTRACT($K7,""ECO.*?C\((\d+/\d+)\)""),"""") "),"") | R7: =IFERROR(__xludf.DUMMYFUNCTION("IFERROR(REGEXEXTRACT($K7,""LING\s*M\((\d+/\d+)\)""),"""") "),"") | S7: =IFERROR(__xludf.DUMMYFUNCTION("IFERROR(REGEXEXTRACT($K7,""LING.*?S\((\d+/\d+)\)""),"""") "),"") | T7: =IFERROR(__xludf.DUMMYFUNCTION("IFERROR(REGEXEXTRACT($K7,""LING[^|]*C\(([0-9]+/[0-9]+)\)""),"""") "),"")
A8: P2 | B8: =IFERROR(VLOOKUP(A8,Projetos!$A$2:$C$7,2,FALSE),"") -> Hybrid Mobile App with Web Panel | C8: P2-TEAM0 | D8: Dev466 | E8: Dev93 | F8: Dev437 | G8: Dev292 | H8: 1 | I8: 1 | K8: DOM M(1/1)[mobile] S(1/1)[web] C(0/1)[] | ECO M(1/2)[ios/ipados] S(0/1)[] C(1/1)[.net] | LING M(1/2)[swift] S(1/2)[javascript] C(1/2)[c#] | L8: =IFERROR(__xludf.DUMMYFUNCTION("IFERROR(REGEXEXTRACT($K8,""DOM\s*M\((\d+/\d+)\)""),"""") "),"1/1") -> 1/1 | M8: =IFERROR(__xludf.DUMMYFUNCTION("IFERROR(REGEXEXTRACT($K8,""DOM.*?S\((\d+/\d+)\)""),"""") "),"1/1") -> 1/1 | N8: =IFERROR(__xludf.DUMMYFUNCTION("IFERROR(REGEXEXTRACT($K8,""DOM.*?C\((\d+/\d+)\)""),"""") "),"0/1") -> 0/1 | O8: =IFERROR(__xludf.DUMMYFUNCTION("IFERROR(REGEXEXTRACT($K8,""ECO\s*M\((\d+/\d+)\)""),"""") "),"1/2") -> 1/2 | P8: =IFERROR(__xludf.DUMMYFUNCTION("IFERROR(REGEXEXTRACT($K8,""ECO.*?S\((\d+/\d+)\)""),"""") "),"0/1") -> 0/1 | Q8: =IFERROR(__xludf.DUMMYFUNCTION("IFERROR(REGEXEXTRACT($K8,""ECO.*?C\((\d+/\d+)\)""),"""") "),"1/1") -> 1/1 | R8: =IFERROR(__xludf.DUMMYFUNCTION("IFERROR(REGEXEXTRACT($K8,""LING\s*M\((\d+/\d+)\)""),"""") "),"1/2") -> 1/2 | S8: =IFERROR(__xludf.DUMMYFUNCTION("IFERROR(REGEXEXTRACT($K8,""LING.*?S\((\d+/\d+)\)""),"""") "),"1/2") -> 1/2 | T8: =IFERROR(__xludf.DUMMYFUNCTION("IFERROR(REGEXEXTRACT($K8,""LING[^|]*C\(([0-9]+/[0-9]+)\)""),"""") "),"1/2") -> 1/2 | U8: =IFERROR(__xludf.DUMMYFUNCTION("AND( VALUE(INDEX(SPLIT(L8,""/""),1))=VALUE(INDEX(SPLIT(L8,""/""),2)), VALUE(INDEX(SPLIT(O8,""/""),1))=VALUE(INDEX(SPLIT(O8,""/""),2)), VALUE(INDEX(SPLIT(R8,""/""),1))=VALUE(INDEX(SPLIT(R8,""/""),2)) ) "),FALSE) -> FALSE | V8: =IFERROR(__xludf.DUMMYFUNCTION("IF($U8=TRUE,""OK"", TEXTJOIN("" | "",TRUE, IF(VALUE(INDEX(SPLIT($L8,""/""),2))-VALUE(INDEX(SPLIT($L8,""/""),1))>0, ""DOM faltam ""&(VALUE(INDEX(SPLIT($L8,""/""),2))-VALUE(INDEX(SPLIT($L8,""/""),1))), """"), IF(VALUE(INDEX(SPLIT($O8,""/""),2))-V"&"ALUE(INDEX(SPLIT($O8,""/""),1))>0, ""ECO faltam ""&(VALUE(INDEX(SPLIT($O8,""/""),2))-VALUE(INDEX(SPLIT($O8,""/""),1))), """"), IF(VALUE(INDEX(SPLIT($R8,""/""),2))-VALUE(INDEX(SPLIT($R8,""/""),1))>0, ""LING faltam ""&(VALUE(INDEX(SPLIT($R8,""/"&"""),2))-VALUE(INDEX(SPLIT($R8,""/""),1))), """") ) ) "),"ECO faltam 1 | LING faltam 1") -> ECO faltam 1 | LING faltam 1 | W8: =IFERROR(__xludf.DUMMYFUNCTION(" (VALUE(INDEX(SPLIT(L8,""/""),2))-VALUE(INDEX(SPLIT(L8,""/""),1))) + (VALUE(INDEX(SPLIT(O8,""/""),2))-VALUE(INDEX(SPLIT(O8,""/""),1))) + (VALUE(INDEX(SPLIT(R8,""/""),2))-VALUE(INDEX(SPLIT(R8,""/""),1))) "),2.0) -> 2 | X8: Domínio: Desktop Ecossistema: .NET Linguagens: C# Match (requisitos do projeto): DOM: M (0/1)[] S (0/1)[] C (0/1)[] ECO: M (0/2)[] S (0/1)[] C (1/1)[.net] LING: M (0/2)[] S (0/2)[] C (1/2)[c#] Colaboração (somente com membros desta equipe): 466-93: SEM_COMUM 466-292: SEM_COMUM 466-437: SEM_COMUM | Y8: Domínio: Desktop Ecossistema: .NET Linguagens: C# Match (requisitos do projeto): DOM: M (0/1)[] S (0/1)[] C (0/1)[] ECO: M (0/2)[] S (0/1)[] C (1/1)[.net] LING: M (0/2)[] S (0/2)[] C (1/2)[c#] Colaboração (somente com membros desta equipe): 93-292: SEM_COMUM 93-437: SEM_COMUM 93-466: SEM_COMUM | Z8: Domínio: Mobile Ecossistema: iOS/iPadOS Linguagens: Swift Match (requisitos do projeto): DOM: M (1/1)[mobile] S (0/1)[] C (0/1)[] ECO: M (1/2)[ios/ipados] S (0/1)[] C (0/1)[] LING: M (1/2)[swift] S (0/2)[] C (0/2)[] Colaboração (somente com membros desta equipe): 437-93: P158(,osf=0.670,slf=0.322); P82(,osf=0.567,slf=0.737); P85(,osf=0.784,slf=0.538) | 437-292: P82(,osf=0.567,slf=0.737) 437-292: SEM_COMUM 437-466: SEM_COMUM | AA8: Domínio: Web Ecossistema: Node.js Linguagens: JavaScript Match (requisitos do projeto): DOM: M (0/1)[] S (1/1)[web] C (0/1)[] ECO: M (0/2)[] S (0/1)[] C (0/1)[] LING: M (0/2)[] S (1/2)[javascript] C (0/2)[] Colaboração (somente com membros desta equipe): 292-93: P82(,osf=0.567,slf=0.737) | 292-437: P82(,osf=0.567,slf=0.737) 292-437: SEM_COMUM 292-466: SEM_COMUM
B9: =IFERROR( "DOM M["&VLOOKUP($A8,Projetos!$A:$L,4,FALSE)&"] S["&VLOOKUP($A8,Projetos!$A:$L,5,FALSE)&"] C["&VLOOKUP($A8,Projetos!$A:$L,6,FALSE)&"]"&CHAR(10)& "ECO M["&VLOOKUP($A8,Projetos!$A:$L,7,FALSE)&"] S["&VLOOKUP($A8,Projetos!$A:$L,8,FALSE)&"] C["&VLOOKUP($A8,Projetos!$A:$L,9,FALSE)&"]"&CHAR(10)& "LING M["&VLOOKUP($A8,Projetos!$A:$L,10,FALSE)&"] S["&VLOOKUP($A8,Projetos!$A:$L,11,FALSE)&"] C["&VLOOKUP($A8,Projetos!$A:$L,12,FALSE)&"]" ,"") -> DOM M[Mobile] S[Web] C[Cloud] ECO M[Android, iOS/iPadOS] S[React] C[.NET] LING M[Kotlin, Swift] S[JavaScript, TypeScript] C[Java, C#] | C9: P2-TEAM1 | D9: Dev270 | E9: Dev411 | F9: Dev479 | G9: Dev503 | H9: 2 | I9: 1 | K9: DOM M(0/1)[] S(1/1)[web] C(0/1)[] | ECO M(0/2)[] S(1/1)[react] C(0/1)[] | LING M(0/2)[] S(2/2)[javascript, typescript] C(1/2)[java] | L9: =IFERROR(__xludf.DUMMYFUNCTION("IFERROR(REGEXEXTRACT($K9,""DOM\s*M\((\d+/\d+)\)""),"""") "),"0/1") -> 0/1 | M9: =IFERROR(__xludf.DUMMYFUNCTION("IFERROR(REGEXEXTRACT($K9,""DOM.*?S\((\d+/\d+)\)""),"""") "),"1/1") -> 1/1 | N9: =IFERROR(__xludf.DUMMYFUNCTION("IFERROR(REGEXEXTRACT($K9,""DOM.*?C\((\d+/\d+)\)""),"""") "),"0/1") -> 0/1 | O9: =IFERROR(__xludf.DUMMYFUNCTION("IFERROR(REGEXEXTRACT($K9,""ECO\s*M\((\d+/\d+)\)""),"""") "),"0/2") -> 0/2 | P9: =IFERROR(__xludf.DUMMYFUNCTION("IFERROR(REGEXEXTRACT($K9,""ECO.*?S\((\d+/\d+)\)""),"""") "),"1/1") -> 1/1 | Q9: =IFERROR(__xludf.DUMMYFUNCTION("IFERROR(REGEXEXTRACT($K9,""ECO.*?C\((\d+/\d+)\)""),"""") "),"0/1") -> 0/1 | R9: =IFERROR(__xludf.DUMMYFUNCTION("IFERROR(REGEXEXTRACT($K9,""LING\s*M\((\d+/\d+)\)""),"""") "),"0/2") -> 0/2 | S9: =IFERROR(__xludf.DUMMYFUNCTION("IFERROR(REGEXEXTRACT($K9,""LING.*?S\((\d+/\d+)\)""),"""") "),"2/2") -> 2/2 | T9: =IFERROR(__xludf.DUMMYFUNCTION("IFERROR(REGEXEXTRACT($K9,""LING[^|]*C\(([0-9]+/[0-9]+)\)""),"""") "),"1/2") -> 1/2 | U9: =IFERROR(__xludf.DUMMYFUNCTION("AND( VALUE(INDEX(SPLIT(L9,""/""),1))=VALUE(INDEX(SPLIT(L9,""/""),2)), VALUE(INDEX(SPLIT(O9,""/""),1))=VALUE(INDEX(SPLIT(O9,""/""),2)), VALUE(INDEX(SPLIT(R9,""/""),1))=VALUE(INDEX(SPLIT(R9,""/""),2)) ) "),FALSE) -> FALSE | V9: =IFERROR(__xludf.DUMMYFUNCTION("IF($U9=TRUE,""OK"", TEXTJOIN("" | "",TRUE, IF(VALUE(INDEX(SPLIT($L9,""/""),2))-VALUE(INDEX(SPLIT($L9,""/""),1))>0, ""DOM faltam ""&(VALUE(INDEX(SPLIT($L9,""/""),2))-VALUE(INDEX(SPLIT($L9,""/""),1))), """"), IF(VALUE(INDEX(SPLIT($O9,""/""),2))-V"&"ALUE(INDEX(SPLIT($O9,""/""),1))>0, ""ECO faltam ""&(VALUE(INDEX(SPLIT($O9,""/""),2))-VALUE(INDEX(SPLIT($O9,""/""),1))), """"), IF(VALUE(INDEX(SPLIT($R9,""/""),2))-VALUE(INDEX(SPLIT($R9,""/""),1))>0, ""LING faltam ""&(VALUE(INDEX(SPLIT($R9,""/"&"""),2))-VALUE(INDEX(SPLIT($R9,""/""),1))), """") ) ) "),"DOM faltam 1 | ECO faltam 2 | LING faltam 2") -> DOM faltam 1 | ECO faltam 2 | LING faltam 2 | W9: =IFERROR(__xludf.DUMMYFUNCTION(" (VALUE(INDEX(SPLIT(L9,""/""),2))-VALUE(INDEX(SPLIT(L9,""/""),1))) + (VALUE(INDEX(SPLIT(O9,""/""),2))-VALUE(INDEX(SPLIT(O9,""/""),1))) + (VALUE(INDEX(SPLIT(R9,""/""),2))-VALUE(INDEX(SPLIT(R9,""/""),1))) "),5.0) -> 5 | X9: Domínio: Web Ecossistema: Angular Linguagens: TypeScript Match (requisitos do projeto): DOM: M (0/1)[] S (1/1)[web] C (0/1)[] ECO: M (0/2)[] S (0/1)[] C (0/1)[] LING: M (0/2)[] S (1/2)[typescript] C (0/2)[] Colaboração (somente com membros desta equipe): 270-411: SEM_COMUM 270-479: SEM_COMUM 270-503: SEM_COMUM | Y9: Domínio: Web Ecossistema: Spring Boot Linguagens: Java Match (requisitos do projeto): DOM: M (0/1)[] S (1/1)[web] C (0/1)[] ECO: M (0/2)[] S (0/1)[] C (0/1)[] LING: M (0/2)[] S (0/2)[] C (1/2)[java] Colaboração (somente com membros desta equipe): 411-270: P82(,osf=0.567,slf=0.737) | 411-479: P179(,osf=0.489,slf=0.711) | 411-503: P145(,osf=0.612,slf=0.871); P177(,osf=0.340,slf=0.621); P284(,osf=0.383,slf=0.553) 411-479: SEM_COMUM 411-503: SEM_COMUM | Z9: Domínio: Web Ecossistema: Angular Linguagens: TypeScript Match (requisitos do projeto): DOM: M (0/1)[] S (1/1)[web] C (0/1)[] ECO: M (0/2)[] S (0/1)[] C (0/1)[] LING: M (0/2)[] S (1/2)[typescript] C (0/2)[] Colaboração (somente com membros desta equipe): 479-270: SEM_COMUM 479-411: P179(,osf=0.489,slf=0.711) 479-503: SEM_COMUM | AA9: Domínio: Web Ecossistema: React Linguagens: JavaScript Match (requisitos do projeto): DOM: M (0/1)[] S (1/1)[web] C (0/1)[] ECO: M (0/2)[] S (1/1)[react] C (0/1)[] LING: M (0/2)[] S (1/2)[javascript] C (0/2)[] Colaboração (somente com membros desta equipe): 503-270: SEM_COMUM 503-411: SEM_COMUM 503-479: SEM_COMUM
C10: P2-TEAM2 | D10: Dev115 | E10: Dev119 | F10: Dev399 | G10: Dev193 | H10: 3 | I10: 2 | K10: DOM M(1/1)[mobile] S(1/1)[web] C(0/1)[] | ECO M(1/2)[ios/ipados] S(0/1)[] C(1/1)[.net] | LING M(1/2)[swift] S(1/2)[javascript] C(2/2)[java, c#] | L10: =IFERROR(__xludf.DUMMYFUNCTION("IFERROR(REGEXEXTRACT($K10,""DOM\s*M\((\d+/\d+)\)""),"""") "),"1/1") -> 1/1 | M10: =IFERROR(__xludf.DUMMYFUNCTION("IFERROR(REGEXEXTRACT($K10,""DOM.*?S\((\d+/\d+)\)""),"""") "),"1/1") -> 1/1 | N10: =IFERROR(__xludf.DUMMYFUNCTION("IFERROR(REGEXEXTRACT($K10,""DOM.*?C\((\d+/\d+)\)""),"""") "),"0/1") -> 0/1 | O10: =IFERROR(__xludf.DUMMYFUNCTION("IFERROR(REGEXEXTRACT($K10,""ECO\s*M\((\d+/\d+)\)""),"""") "),"1/2") -> 1/2 | P10: =IFERROR(__xludf.DUMMYFUNCTION("IFERROR(REGEXEXTRACT($K10,""ECO.*?S\((\d+/\d+)\)""),"""") "),"0/1") -> 0/1 | Q10: =IFERROR(__xludf.DUMMYFUNCTION("IFERROR(REGEXEXTRACT($K10,""ECO.*?C\((\d+/\d+)\)""),"""") "),"1/1") -> 1/1 | R10: =IFERROR(__xludf.DUMMYFUNCTION("IFERROR(REGEXEXTRACT($K10,""LING\s*M\((\d+/\d+)\)""),"""") "),"1/2") -> 1/2 | S10: =IFERROR(__xludf.DUMMYFUNCTION("IFERROR(REGEXEXTRACT($K10,""LING.*?S\((\d+/\d+)\)""),"""") "),"1/2") -> 1/2 | T10: =IFERROR(__xludf.DUMMYFUNCTION("IFERROR(REGEXEXTRACT($K10,""LING[^|]*C\(([0-9]+/[0-9]+)\)""),"""") "),"2/2") -> 2/2 | U10: =IFERROR(__xludf.DUMMYFUNCTION("AND( VALUE(INDEX(SPLIT(L10,""/""),1))=VALUE(INDEX(SPLIT(L10,""/""),2)), VALUE(INDEX(SPLIT(O10,""/""),1))=VALUE(INDEX(SPLIT(O10,""/""),2)), VALUE(INDEX(SPLIT(R10,""/""),1))=VALUE(INDEX(SPLIT(R10,""/""),2)) ) "),FALSE) -> FALSE | V10: =IFERROR(__xludf.DUMMYFUNCTION("IF($U10=TRUE,""OK"", TEXTJOIN("" | "",TRUE, IF(VALUE(INDEX(SPLIT($L10,""/""),2))-VALUE(INDEX(SPLIT($L10,""/""),1))>0, ""DOM faltam ""&(VALUE(INDEX(SPLIT($L10,""/""),2))-VALUE(INDEX(SPLIT($L10,""/""),1))), """"), IF(VALUE(INDEX(SPLIT($O10,""/"")"&",2))-VALUE(INDEX(SPLIT($O10,""/""),1))>0, ""ECO faltam ""&(VALUE(INDEX(SPLIT($O10,""/""),2))-VALUE(INDEX(SPLIT($O10,""/""),1))), """"), IF(VALUE(INDEX(SPLIT($R10,""/""),2))-VALUE(INDEX(SPLIT($R10,""/""),1))>0, ""LING faltam ""&(VALUE(INDEX(SPL"&"IT($R10,""/""),2))-VALUE(INDEX(SPLIT($R10,""/""),1))), """") ) ) "),"ECO faltam 1 | LING faltam 1") -> ECO faltam 1 | LING faltam 1 | W10: =IFERROR(__xludf.DUMMYFUNCTION(" (VALUE(INDEX(SPLIT(L10,""/""),2))-VALUE(INDEX(SPLIT(L10,""/""),1))) + (VALUE(INDEX(SPLIT(O10,""/""),2))-VALUE(INDEX(SPLIT(O10,""/""),1))) + (VALUE(INDEX(SPLIT(R10,""/""),2))-VALUE(INDEX(SPLIT(R10,""/""),1))) "),2.0) -> 2 | X10: Domínio: Web Ecossistema: Node.js Linguagens: JavaScript Match (requisitos do projeto): DOM: M (0/1)[] S (1/1)[web] C (0/1)[] ECO: M (0/2)[] S (0/1)[] C (0/1)[] LING: M (0/2)[] S (1/2)[javascript] C (0/2)[] Colaboração (somente com membros desta equipe): 115-119: SEM_COMUM 115-193: SEM_COMUM 115-399: SEM_COMUM | Y10: Domínio: Mobile Ecossistema: iOS/iPadOS Linguagens: Swift Match (requisitos do projeto): DOM: M (1/1)[mobile] S (0/1)[] C (0/1)[] ECO: M (1/2)[ios/ipados] S (0/1)[] C (0/1)[] LING: M (1/2)[swift] S (0/2)[] C (0/2)[] Colaboração (somente com membros desta equipe): 119-115: SEM_COMUM 119-193: P82(,osf=0.567,slf=0.737) | 119-399: P82(,osf=0.567,slf=0.737) 119-399: SEM_COMUM | Z10: Domínio: Desktop Ecossistema: .NET Linguagens: C# Match (requisitos do projeto): DOM: M (0/1)[] S (0/1)[] C (0/1)[] ECO: M (0/2)[] S (0/1)[] C (1/1)[.net] LING: M (0/2)[] S (0/2)[] C (1/2)[c#] Colaboração (somente com membros desta equipe): 399-115: SEM_COMUM 399-119: P82(,osf=0.567,slf=0.737) | 399-193: P82(,osf=0.567,slf=0.737); P85(,osf=0.784,slf=0.538) 399-193: SEM_COMUM | AA10: Domínio: Web Ecossistema: Spring Boot Linguagens: Java Match (requisitos do projeto): DOM: M (0/1)[] S (1/1)[web] C (0/1)[] ECO: M (0/2)[] S (0/1)[] C (0/1)[] LING: M (0/2)[] S (0/2)[] C (1/2)[java] Colaboração (somente com membros desta equipe): 193-115: SEM_COMUM 193-119: SEM_COMUM 193-399: SEM_COMUM
C11: P2-TEAM3 | D11: Dev468 | E11: Dev263 | F11: Dev503 | G11: Dev5 | H11: 4 | I11: 4 | K11: DOM M(1/1)[mobile] S(1/1)[web] C(1/1)[cloud] | ECO M(1/2)[android] S(1/1)[react] C(0/1)[] | LING M(1/2)[kotlin] S(1/2)[javascript] C(0/2)[] | L11: =IFERROR(__xludf.DUMMYFUNCTION("IFERROR(REGEXEXTRACT($K11,""DOM\s*M\((\d+/\d+)\)""),"""") "),"1/1") -> 1/1 | M11: =IFERROR(__xludf.DUMMYFUNCTION("IFERROR(REGEXEXTRACT($K11,""DOM.*?S\((\d+/\d+)\)""),"""") "),"1/1") -> 1/1 | N11: =IFERROR(__xludf.DUMMYFUNCTION("IFERROR(REGEXEXTRACT($K11,""DOM.*?C\((\d+/\d+)\)""),"""") "),"1/1") -> 1/1 | O11: =IFERROR(__xludf.DUMMYFUNCTION("IFERROR(REGEXEXTRACT($K11,""ECO\s*M\((\d+/\d+)\)""),"""") "),"1/2") -> 1/2 | P11: =IFERROR(__xludf.DUMMYFUNCTION("IFERROR(REGEXEXTRACT($K11,""ECO.*?S\((\d+/\d+)\)""),"""") "),"1/1") -> 1/1 | Q11: =IFERROR(__xludf.DUMMYFUNCTION("IFERROR(REGEXEXTRACT($K11,""ECO.*?C\((\d+/\d+)\)""),"""") "),"0/1") -> 0/1 | R11: =IFERROR(__xludf.DUMMYFUNCTION("IFERROR(REGEXEXTRACT($K11,""LING\s*M\((\d+/\d+)\)""),"""") "),"1/2") -> 1/2 | S11: =IFERROR(__xludf.DUMMYFUNCTION("IFERROR(REGEXEXTRACT($K11,""LING.*?S\((\d+/\d+)\)""),"""") "),"1/2") -> 1/2 | T11: =IFERROR(__xludf.DUMMYFUNCTION("IFERROR(REGEXEXTRACT($K11,""LING[^|]*C\(([0-9]+/[0-9]+)\)""),"""") "),"0/2") -> 0/2 | U11: =IFERROR(__xludf.DUMMYFUNCTION("AND( VALUE(INDEX(SPLIT(L11,""/""),1))=VALUE(INDEX(SPLIT(L11,""/""),2)), VALUE(INDEX(SPLIT(O11,""/""),1))=VALUE(INDEX(SPLIT(O11,""/""),2)), VALUE(INDEX(SPLIT(R11,""/""),1))=VALUE(INDEX(SPLIT(R11,""/""),2)) ) "),FALSE) -> FALSE | V11: =IFERROR(__xludf.DUMMYFUNCTION("IF($U11=TRUE,""OK"", TEXTJOIN("" | "",TRUE, IF(VALUE(INDEX(SPLIT($L11,""/""),2))-VALUE(INDEX(SPLIT($L11,""/""),1))>0, ""DOM faltam ""&(VALUE(INDEX(SPLIT($L11,""/""),2))-VALUE(INDEX(SPLIT($L11,""/""),1))), """"), IF(VALUE(INDEX(SPLIT($O11,""/"")"&",2))-VALUE(INDEX(SPLIT($O11,""/""),1))>0, ""ECO faltam ""&(VALUE(INDEX(SPLIT($O11,""/""),2))-VALUE(INDEX(SPLIT($O11,""/""),1))), """"), IF(VALUE(INDEX(SPLIT($R11,""/""),2))-VALUE(INDEX(SPLIT($R11,""/""),1))>0, ""LING faltam ""&(VALUE(INDEX(SPL"&"IT($R11,""/""),2))-VALUE(INDEX(SPLIT($R11,""/""),1))), """") ) ) "),"ECO faltam 1 | LING faltam 1") -> ECO faltam 1 | LING faltam 1 | W11: =IFERROR(__xludf.DUMMYFUNCTION(" (VALUE(INDEX(SPLIT(L11,""/""),2))-VALUE(INDEX(SPLIT(L11,""/""),1))) + (VALUE(INDEX(SPLIT(O11,""/""),2))-VALUE(INDEX(SPLIT(O11,""/""),1))) + (VALUE(INDEX(SPLIT(R11,""/""),2))-VALUE(INDEX(SPLIT(R11,""/""),1))) "),2.0) -> 2 | X11: Domínio: Cloud Ecossistema: AWS Lambda Linguagens: Python Match (requisitos do projeto): DOM: M (0/1)[] S (0/1)[] C (1/1)[cloud] ECO: M (0/2)[] S (0/1)[] C (0/1)[] LING: M (0/2)[] S (0/2)[] C (0/2)[] Colaboração (somente com membros desta equipe): 468-5: P82(,osf=0.567,slf=0.737) | 468-508: P196(,osf=0.888,slf=0.339) | 468-516: P82(,osf=0.567,slf=0.737); P85(,osf=0.784,slf=0.538) 468-263: SEM_COMUM 468-503: SEM_COMUM | Y11: Domínio: Web Ecossistema: Vue Linguagens: JavaScript Match (requisitos do projeto): DOM: M (0/1)[] S (1/1)[web] C (0/1)[] ECO: M (0/2)[] S (0/1)[] C (0/1)[] LING: M (0/2)[] S (1/2)[javascript] C (0/2)[] Colaboração (somente com membros desta equipe): 263-5: P179(,osf=0.489,slf=0.711) | 263-145: P179(,osf=0.489,slf=0.711); P201(,osf=0.535,slf=0.596) 263-468: SEM_COMUM 263-503: SEM_COMUM | Z11: Domínio: Web Ecossistema: React Linguagens: JavaScript Match (requisitos do projeto): DOM: M (0/1)[] S (1/1)[web] C (0/1)[] ECO: M (0/2)[] S (1/1)[react] C (0/1)[] LING: M (0/2)[] S (1/2)[javascript] C (0/2)[] Colaboração (somente com membros desta equipe): 503-5: P145(,osf=0.612,slf=0.871); P177(,osf=0.340,slf=0.621); P213(,osf=0.312,slf=0.608); P216(,osf=0.401,slf=0.341); P279(,osf=0.594,slf=0.422) | 503-411: P145(,osf=0.612,slf=0.871); P177(,osf=0.340,slf=0.621); P284(,osf=0.383,slf=0.553) 503-263: SEM_COMUM 503-468: SEM_COMUM | AA11: Domínio: Mobile Ecossistema: Android Linguagens: Kotlin Match (requisitos do projeto): DOM: M (1/1)[mobile] S (0/1)[] C (0/1)[] ECO: M (1/2)[android] S (0/1)[] C (0/1)[] LING: M (1/2)[kotlin] S (0/2)[] C (0/2)[] Colaboração (somente com membros desta equipe): 5-263: P179(,osf=0.489,slf=0.711) | 5-468: P82(,osf=0.567,slf=0.737) | 5-503: P145(,osf=0.612,slf=0.871); P177(,osf=0.340,slf=0.621); P213(,osf=0.312,slf=0.608); P216(,osf=0.401,slf=0.341); P279(,osf=0.594,slf=0.422) 5-468: SEM_COMUM 5-503: SEM_COMUM
C12: P2-TEAM4 | D12: Dev104 | E12: Dev363 | F12: Dev544 | G12: Dev81 | H12: 3 | I12: 4 | K12: DOM M(1/1)[mobile] S(0/1)[] C(0/1)[] | ECO M(2/2)[android, ios/ipados] S(0/1)[] C(0/1)[] | LING M(2/2)[kotlin, swift] S(1/2)[javascript] C(0/2)[] | L12: =IFERROR(__xludf.DUMMYFUNCTION("IFERROR(REGEXEXTRACT($K12,""DOM\s*M\((\d+/\d+)\)""),"""") "),"1/1") -> 1/1 | M12: =IFERROR(__xludf.DUMMYFUNCTION("IFERROR(REGEXEXTRACT($K12,""DOM.*?S\((\d+/\d+)\)""),"""") "),"0/1") -> 0/1 | N12: =IFERROR(__xludf.DUMMYFUNCTION("IFERROR(REGEXEXTRACT($K12,""DOM.*?C\((\d+/\d+)\)""),"""") "),"0/1") -> 0/1 | O12: =IFERROR(__xludf.DUMMYFUNCTION("IFERROR(REGEXEXTRACT($K12,""ECO\s*M\((\d+/\d+)\)""),"""") "),"2/2") -> 2/2 | P12: =IFERROR(__xludf.DUMMYFUNCTION("IFERROR(REGEXEXTRACT($K12,""ECO.*?S\((\d+/\d+)\)""),"""") "),"0/1") -> 0/1 | Q12: =IFERROR(__xludf.DUMMYFUNCTION("IFERROR(REGEXEXTRACT($K12,""ECO.*?C\((\d+/\d+)\)""),"""") "),"0/1") -> 0/1 | R12: =IFERROR(__xludf.DUMMYFUNCTION("IFERROR(REGEXEXTRACT($K12,""LING\s*M\((\d+/\d+)\)""),"""") "),"2/2") -> 2/2 | S12: =IFERROR(__xludf.DUMMYFUNCTION("IFERROR(REGEXEXTRACT($K12,""LING.*?S\((\d+/\d+)\)""),"""") "),"1/2") -> 1/2 | T12: =IFERROR(__xludf.DUMMYFUNCTION("IFERROR(REGEXEXTRACT($K12,""LING[^|]*C\(([0-9]+/[0-9]+)\)""),"""") "),"0/2") -> 0/2 | U12: =IFERROR(__xludf.DUMMYFUNCTION("AND( VALUE(INDEX(SPLIT(L12,""/""),1))=VALUE(INDEX(SPLIT(L12,""/""),2)), VALUE(INDEX(SPLIT(O12,""/""),1))=VALUE(INDEX(SPLIT(O12,""/""),2)), VALUE(INDEX(SPLIT(R12,""/""),1))=VALUE(INDEX(SPLIT(R12,""/""),2)) ) "),TRUE) -> TRUE | V12: =IFERROR(__xludf.DUMMYFUNCTION("IF($U12=TRUE,""OK"", TEXTJOIN("" | "",TRUE, IF(VALUE(INDEX(SPLIT($L12,""/""),2))-VALUE(INDEX(SPLIT($L12,""/""),1))>0, ""DOM faltam ""&(VALUE(INDEX(SPLIT($L12,""/""),2))-VALUE(INDEX(SPLIT($L12,""/""),1))), """"), IF(VALUE(INDEX(SPLIT($O12,""/"")"&",2))-VALUE(INDEX(SPLIT($O12,""/""),1))>0, ""ECO faltam ""&(VALUE(INDEX(SPLIT($O12,""/""),2))-VALUE(INDEX(SPLIT($O12,""/""),1))), """"), IF(VALUE(INDEX(SPLIT($R12,""/""),2))-VALUE(INDEX(SPLIT($R12,""/""),1))>0, ""LING faltam ""&(VALUE(INDEX(SPL"&"IT($R12,""/""),2))-VALUE(INDEX(SPLIT($R12,""/""),1))), """") ) ) "),"OK") -> OK | W12: =IFERROR(__xludf.DUMMYFUNCTION(" (VALUE(INDEX(SPLIT(L12,""/""),2))-VALUE(INDEX(SPLIT(L12,""/""),1))) + (VALUE(INDEX(SPLIT(O12,""/""),2))-VALUE(INDEX(SPLIT(O12,""/""),1))) + (VALUE(INDEX(SPLIT(R12,""/""),2))-VALUE(INDEX(SPLIT(R12,""/""),1))) "),0.0) -> 0 | X12: Domínio: Mobile Ecossistema: Android Linguagens: Kotlin Match (requisitos do projeto): DOM: M (1/1)[mobile] S (0/1)[] C (0/1)[] ECO: M (1/2)[android] S (0/1)[] C (0/1)[] LING: M (1/2)[kotlin] S (0/2)[] C (0/2)[] Colaboração (somente com membros desta equipe): 104-81: P69(,osf=0.478,slf=0.301) 104-363: SEM_COMUM 104-544: SEM_COMUM | Y12: Domínio: Mobile Ecossistema: iOS/iPadOS Linguagens: Swift Match (requisitos do projeto): DOM: M (1/1)[mobile] S (0/1)[] C (0/1)[] ECO: M (1/2)[ios/ipados] S (0/1)[] C (0/1)[] LING: M (1/2)[swift] S (0/2)[] C (0/2)[] Colaboração (somente com membros desta equipe): 363-81: SEM_COMUM 363-104: SEM_COMUM 363-544: SEM_COMUM | Z12: Domínio: Mobile Ecossistema: iOS/iPadOS Linguagens: Swift Match (requisitos do projeto): DOM: M (1/1)[mobile] S (0/1)[] C (0/1)[] ECO: M (1/2)[ios/ipados] S (0/1)[] C (0/1)[] LING: M (1/2)[swift] S (0/2)[] C (0/2)[] Colaboração (somente com membros desta equipe): 544-81: SEM_COMUM 544-104: SEM_COMUM 544-363: SEM_COMUM | AA12: Domínio: IoT Ecossistema: nan Linguagens: JavaScript Match (requisitos do projeto): DOM: M (0/1)[] S (0/1)[] C (0/1)[] ECO: M (0/2)[] S (0/1)[] C (0/1)[] LING: M (0/2)[] S (1/2)[javascript] C (0/2)[] Colaboração (somente com membros desta equipe): 81-104: P69(,osf=0.478,slf=0.301) 81-363: SEM_COMUM 81-544: SEM_COMUM
L13: =IFERROR(__xludf.DUMMYFUNCTION("IFERROR(REGEXEXTRACT($K13,""DOM\s*M\((\d+/\d+)\)""),"""") "),"") | M13: =IFERROR(__xludf.DUMMYFUNCTION("IFERROR(REGEXEXTRACT($K13,""DOM.*?S\((\d+/\d+)\)""),"""") "),"") | N13: =IFERROR(__xludf.DUMMYFUNCTION("IFERROR(REGEXEXTRACT($K13,""DOM.*?C\((\d+/\d+)\)""),"""") "),"") | O13: =IFERROR(__xludf.DUMMYFUNCTION("IFERROR(REGEXEXTRACT($K13,""ECO\s*M\((\d+/\d+)\)""),"""") "),"") | P13: =IFERROR(__xludf.DUMMYFUNCTION("IFERROR(REGEXEXTRACT($K13,""ECO.*?S\((\d+/\d+)\)""),"""") "),"") | Q13: =IFERROR(__xludf.DUMMYFUNCTION("IFERROR(REGEXEXTRACT($K13,""ECO.*?C\((\d+/\d+)\)""),"""") "),"") | R13: =IFERROR(__xludf.DUMMYFUNCTION("IFERROR(REGEXEXTRACT($K13,""LING\s*M\((\d+/\d+)\)""),"""") "),"") | S13: =IFERROR(__xludf.DUMMYFUNCTION("IFERROR(REGEXEXTRACT($K13,""LING.*?S\((\d+/\d+)\)""),"""") "),"") | T13: =IFERROR(__xludf.DUMMYFUNCTION("IFERROR(REGEXEXTRACT($K13,""LING[^|]*C\(([0-9]+/[0-9]+)\)""),"""") "),"")
A14: P3 | B14: =IFERROR(VLOOKUP(A14,Projetos!$A$2:$C$7,2,FALSE),"") -> Cloud IoT Sensor Platform | C14: P3-TEAM0 | D14: Dev423 | E14: Dev558 | F14: Dev494 | G14: Dev391 | H14: 3 | I14: 2 | K14: DOM M(1/2)[cloud] S(1/1)[web] C(0/1)[] | ECO M(1/1)[aws lambda] S(1/3)[react] C(1/1)[android] | LING M(1/2)[python] S(1/1)[javascript] C(0/2)[] | L14: =IFERROR(__xludf.DUMMYFUNCTION("IFERROR(REGEXEXTRACT($K14,""DOM\s*M\((\d+/\d+)\)""),"""") "),"1/2") -> 1/2 | M14: =IFERROR(__xludf.DUMMYFUNCTION("IFERROR(REGEXEXTRACT($K14,""DOM.*?S\((\d+/\d+)\)""),"""") "),"1/1") -> 1/1 | N14: =IFERROR(__xludf.DUMMYFUNCTION("IFERROR(REGEXEXTRACT($K14,""DOM.*?C\((\d+/\d+)\)""),"""") "),"0/1") -> 0/1 | O14: =IFERROR(__xludf.DUMMYFUNCTION("IFERROR(REGEXEXTRACT($K14,""ECO\s*M\((\d+/\d+)\)""),"""") "),"1/1") -> 1/1 | P14: =IFERROR(__xludf.DUMMYFUNCTION("IFERROR(REGEXEXTRACT($K14,""ECO.*?S\((\d+/\d+)\)""),"""") "),"1/3") -> 1/3 | Q14: =IFERROR(__xludf.DUMMYFUNCTION("IFERROR(REGEXEXTRACT($K14,""ECO.*?C\((\d+/\d+)\)""),"""") "),"1/1") -> 1/1 | R14: =IFERROR(__xludf.DUMMYFUNCTION("IFERROR(REGEXEXTRACT($K14,""LING\s*M\((\d+/\d+)\)""),"""") "),"1/2") -> 1/2 | S14: =IFERROR(__xludf.DUMMYFUNCTION("IFERROR(REGEXEXTRACT($K14,""LING.*?S\((\d+/\d+)\)""),"""") "),"1/1") -> 1/1 | T14: =IFERROR(__xludf.DUMMYFUNCTION("IFERROR(REGEXEXTRACT($K14,""LING[^|]*C\(([0-9]+/[0-9]+)\)""),"""") "),"0/2") -> 0/2 | U14: =IFERROR(__xludf.DUMMYFUNCTION("AND( VALUE(INDEX(SPLIT(L14,""/""),1))=VALUE(INDEX(SPLIT(L14,""/""),2)), VALUE(INDEX(SPLIT(O14,""/""),1))=VALUE(INDEX(SPLIT(O14,""/""),2)), VALUE(INDEX(SPLIT(R14,""/""),1))=VALUE(INDEX(SPLIT(R14,""/""),2)) ) "),FALSE) -> FALSE | V14: =IFERROR(__xludf.DUMMYFUNCTION("IF($U14=TRUE,""OK"", TEXTJOIN("" | "",TRUE, IF(VALUE(INDEX(SPLIT($L14,""/""),2))-VALUE(INDEX(SPLIT($L14,""/""),1))>0, ""DOM faltam ""&(VALUE(INDEX(SPLIT($L14,""/""),2))-VALUE(INDEX(SPLIT($L14,""/""),1))), """"), IF(VALUE(INDEX(SPLIT($O14,""/"")"&",2))-VALUE(INDEX(SPLIT($O14,""/""),1))>0, ""ECO faltam ""&(VALUE(INDEX(SPLIT($O14,""/""),2))-VALUE(INDEX(SPLIT($O14,""/""),1))), """"), IF(VALUE(INDEX(SPLIT($R14,""/""),2))-VALUE(INDEX(SPLIT($R14,""/""),1))>0, ""LING faltam ""&(VALUE(INDEX(SPL"&"IT($R14,""/""),2))-VALUE(INDEX(SPLIT($R14,""/""),1))), """") ) ) "),"DOM faltam 1 | LING faltam 1") -> DOM faltam 1 | LING faltam 1 | W14: =IFERROR(__xludf.DUMMYFUNCTION(" (VALUE(INDEX(SPLIT(L14,""/""),2))-VALUE(INDEX(SPLIT(L14,""/""),1))) + (VALUE(INDEX(SPLIT(O14,""/""),2))-VALUE(INDEX(SPLIT(O14,""/""),1))) + (VALUE(INDEX(SPLIT(R14,""/""),2))-VALUE(INDEX(SPLIT(R14,""/""),1))) "),2.0) -> 2 | X14: Domínio: Web Ecossistema: React Linguagens: JavaScript Match (requisitos do projeto): DOM: M (0/2)[] S (1/1)[web] C (0/1)[] ECO: M (0/1)[] S (1/3)[react] C (0/1)[] LING: M (0/2)[] S (1/1)[javascript] C (0/2)[] Colaboração (somente com membros desta equipe): 423-391: SEM_COMUM 423-494: SEM_COMUM 423-558: P85(,osf=0.784,slf=0.538) | Y14: Domínio: Mobile Ecossistema: Android Linguagens: Kotlin Match (requisitos do projeto): DOM: M (0/2)[] S (0/1)[] C (0/1)[] ECO: M (0/1)[] S (0/3)[] C (1/1)[android] LING: M (0/2)[] S (0/1)[] C (0/2)[] Colaboração (somente com membros desta equipe): 558-391: SEM_COMUM 558-423: SEM_COMUM 558-494: SEM_COMUM | Z14: Domínio: Cloud Ecossistema: AWS Lambda Linguagens: Python Match (requisitos do projeto): DOM: M (1/2)[cloud] S (0/1)[] C (0/1)[] ECO: M (1/1)[aws lambda] S (0/3)[] C (0/1)[] LING: M (1/2)[python] S (0/1)[] C (0/2)[] Colaboração (somente com membros desta equipe): 494-391: SEM_COMUM 494-423: SEM_COMUM 494-558: SEM_COMUM | AA14: Domínio: Cloud Ecossistema: AWS Lambda Linguagens: Python Match (requisitos do projeto): DOM: M (1/2)[cloud] S (0/1)[] C (0/1)[] ECO: M (1/1)[aws lambda] S (0/3)[] C (0/1)[] LING: M (1/2)[python] S (0/1)[] C (0/2)[] Colaboração (somente com membros desta equipe): 391-423: SEM_COMUM 391-494: SEM_COMUM 391-558: SEM_COMUM
